Workbook

Sheet Notice d'utilisation
B2: NOTICE D'UTILISATION
B3: Configurateur de devis – A.R.C ALUMINIUM
B5: ⚠ IMPORTANT – À LIRE EN PREMIER
B6: Ce configurateur est mis à disposition pour les CHÂSSIS STANDARD uniquement. Il ne couvre pas l'intégralité du savoir-faire d'A.R.C ALUMINIUM. Pour tout châssis spécifique (dimensions hors abaques, profils particuliers, finitions sur-mesure, systèmes non listés, performances renforcées, etc.), merci d'adresser directement votre demande au bureau d'études A.R.C ALUMINIUM : 📧 contact@arc-alu.fr 📞 +33 (0)4 76 55 09 64 📍 156 rue Émile Romanet – 38340 VOREPPE 💡 Les plans des menuiseries peuvent être demandés au bureau d'études sur simple demande. 📦 Les tarifs affichés sont calibrés pour des quantités unitaires ou de faibles séries. Pour les commandes en grande quantité ou séries répétitives, A.R.C ALUMINIUM est en mesure de proposer des conditions tarifaires négociées — n'hésitez pas à nous consulter en amont.
B8: LES ONGLETS DU CLASSEUR
B9: « Notice d'utilisation » | C9: Ce document.
B10: « Paramètres » | C10: Permet d'ajuster le taux de remise client appliqué automatiquement à tous les devis. Cellule jaune modifiable (B2).
B11: « Sommaire » | C11: Récapitulatif des grilles de prix et des familles de couleurs disponibles. Pour consultation uniquement.
B12: « Configurateur » | C12: Devis rapide pour 1 seule menuiserie. Saisir Type / Largeur / Hauteur / Couleur / Vitrage / Dormant / Quantité dans les cellules JAUNES. Le prix net HT s'affiche en bas.
B13: « Devis » | C13: Devis multi-lignes complet (jusqu'à 10 menuiseries). C'est l'outil principal pour générer un devis structuré.
B15: COMMENT REMPLIR UN DEVIS (onglet « Devis »)
B16: 1 – Informations chantier | C16: Remplir le bloc en haut : Nom du chantier, Adresse, Référence affaire. La date se met automatiquement.
B17: 2 – Performances (optionnel) | C17: Indiquer les performances souhaitées : Uw (thermique), Sw (facteur solaire), Affaiblissement acoustique, classement AEV. Sert d'orientation au BE.
B18: 3 – Demandeur | C18: Vérifier que l'émetteur, la société et les coordonnées sont à jour.
B19: 4 – Saisie ligne par ligne | C19: Pour chaque ligne du tableau, sélectionner dans les listes déroulantes : Type de menuiserie, Famille couleur, Vitrage, Type de dormant. Saisir Largeur, Hauteur, Quantité. Renseigner si besoin les Options Traverses/Meneaux et l'Option porte. Les Commentaires position se génèrent automatiquement.
B20: 5 – Vérification | C20: Le prix unitaire et le prix total se calculent en temps réel. Le total HT global apparaît en bas du tableau.
B21: 6 – Validation & commande | C21: Lorsqu'un devis saisi sur ce configurateur est validé pour passage en commande, merci de nous transmettre une copie de ce fichier Excel en pièce jointe à votre commande. Cela facilite le traitement et la traçabilité de l'affaire.
B23: SIGNAUX VISUELS À REPÉRER
B24: Cellule LARGEUR ou HAUTEUR sur fond ROUGE | C24: La dimension saisie est hors abaque pour ce type de menuiserie. Le prix unitaire ne s'affiche pas et le devis ne peut pas être validé pour cette ligne. Voir les abaques ci-dessous ou contacter le bureau d'études.
B25: « ⚠ Hors abaque (L X–Y / H X–Y mm) » dans Commentaires position | C25: Détail textuel du dépassement avec les valeurs autorisées rappelées.
B26: « ⚠ Option valable uniquement pour Porte Lourde » | C26: L'option porte sélectionnée (ventouse, anti-panique, etc.) n'est compatible qu'avec les Portes Lourdes. Changer le type ou enlever l'option.
B27: « ⚠ Option T/M incompatible avec la gamme » | C27: Une option Traverse/Meneau a été sélectionnée mais n'est pas applicable à ce type de menuiserie.
B28: Cellule PRIX vide | C28: Soit la ligne n'est pas complète, soit les dimensions sont hors abaque. Vérifier la saisie.
B30: ABAQUES DE DIMENSIONS (par type de menuiserie)
B31: Type de menuiserie | C31: Limites Largeur × Hauteur (mm)
B32: Coulissant 2 vantaux 2 rails | C32: 800 – 3500 / 750 – 2700
B33: Coulissant 3 vantaux 2 rails | C33: 2000 – 5000 / 750 – 2700
B34: Coulissant 4 vantaux 2 rails | C34: 2500 – 6050 / 750 – 2700
B35: Coulissant 3 vantaux 3 rails | C35: 2000 – 5000 / 750 – 2700
B36: Coulissant 6 vantaux 3 rails | C36: 4000 – 6400 / 750 – 2700
B37: Galandage 1 vantail 1 rail | C37: 500 – 2000 / 750 – 2350
B38: Galandage 2 vantaux 1 rail | C38: 900 – 3200 / 750 – 2350
B39: Galandage 2 vantaux 2 rails | C39: 1000 – 3300 / 750 – 2350
B40: Galandage 4 vantaux 2 rails | C40: 1800 – 4100 / 750 – 2350
B41: Châssis fixe vitré | C41: 300 – 3000 / 450 – 2550
B42: Porte Lourde 1 vantail | C42: 800 – 1300 / 1950 – 2850
... B47: Fenêtre OB 2 vantaux | C47: 700 – 2400 / 550 – 2500
B49: Hors de ces plages → demande au bureau d'études A.R.C ALUMINIUM.
B51: PROPRIÉTÉ ET CONFIDENTIALITÉ
B52: Le présent configurateur ainsi que l'ensemble de son contenu — grilles tarifaires, formules de calcul, abaques, méthodologie, structure et données associées — sont la propriété exclusive d'A.R.C ALUMINIUM. Ce document est strictement confidentiel et destiné à un usage exclusivement professionnel, dans le cadre d'une relation commerciale établie avec A.R.C ALUMINIUM. Toute reproduction, diffusion à des tiers, communication ou exploitation, totale ou partielle, à des fins autres que la consultation tarifaire pour les besoins propres du destinataire, est strictement interdite sans autorisation écrite préalable d'A.R.C ALUMINIUM.
...

Sheet Paramètres
A1: PARAMÈTRES
A2: Taux de remise client : | B2: 0.515 | C2: ← Modifier ici
A4: MODE D'EMPLOI
A5: 1. Saisir le taux de remise dans la cellule jaune ci-dessus (cellule B2).
A6: Exemple : 25 % de remise → taper 25 % ou 0,25
A8: 2. Tous les onglets de prix se mettent à jour automatiquement :
A9: • Sur chaque grille Coulissant / Galandage, une section
A10: « PRIX NET CLIENT » apparaît sous le tableau tarif.
A11: • Sur l'onglet « Doubles Vitrages », la colonne « Plus-Value nette »
A12: affiche la plus-value après remise.
A13: • Sur l'onglet « Options dormant », une colonne « Plus value nette »
A14: est également ajoutée.
A16: 3. La grille tarif d'origine (en €) reste toujours visible pour référence.
A18: 4. Pour reprendre le tarif de base sans remise : taper 0 % dans la cellule.

Sheet Sommaire
A1: A.R.C ALUMINIUM — GRILLES DE PRIX (Coulissants & Galandages)
A2: 👉 « Paramètres » : taux de remise — « Configurateur » : devis rapide 1 menuiserie — « Devis » : devis multi-lignes complet
A3: Configuration | B3: Onglet | C3: Largeurs (mm) | D3: Hauteurs (mm)
A4: COULISSANTS
A5: Coulissant 2 vantaux & 2 rails | B5: Coulissant 2 vantaux 2 rails | C5: 800 – 3500 | D5: 750 – 2700
A6: Coulissant 3 vantaux & 2 rails | B6: Coulissant 3 vantaux 2 rails | C6: 2000 – 5000 | D6: 750 – 2700
A7: Coulissant 4 vantaux & 2 rails | B7: Coulissant 4 vantaux 2 rails | C7: 2500 – 6050 | D7: 750 – 2700
A8: Coulissant 3 vantaux & 3 rails | B8: Coulissant 3 vantaux 3 rails | C8: 2000 – 5000 | D8: 750 – 2700
A9: Coulissant 6 vantaux & 3 rails | B9: Coulissant 6 vantaux 3 rails | C9: 4000 – 6400 | D9: 750 – 2700
A11: GALANDAGES
A12: Galandage 1 vantail & 1 rail | B12: Galandage 1 vantail 1 rail | C12: 500 – 2000 | D12: 750 – 2350
A13: Galandage 2 vantaux & 1 rail | B13: Galandage 2 vantaux 1 rail | C13: 900 – 3200 | D13: 750 – 2350
A14: Galandage 2 vantaux & 2 rails | B14: Galandage 2 vantaux 2 rails | C14: 1000 – 3300 | D14: 750 – 2350
A15: Galandage 4 vantaux & 2 rails | B15: Galandage 4 vantaux 2 rails | C15: 1800 – 4100 | D15: 750 – 2350
A17: CHÂSSIS FIXES VITRÉS
A18: Châssis fixe vitré (avec dormant visible) | B18: Châssis fixe vitré | C18: 300 – 3000 | D18: 450 – 2550
A20: PORTES LOURDES ACCESS
A21: Porte Lourde 1 vantail (ouvrant visible) | B21: Porte Lourde 1 vantail | C21: 800 – 1300 | D21: 1950 – 2850
A22: Porte Lourde 2 vantaux (ouvrant visible) | B22: Porte Lourde 2 vantaux | C22: 1200 – 2500 | D22: 1950 – 2850
A24: FENÊTRES / PORTES-FENÊTRES
A25: Fenêtre/Porte-fenêtre OF 1 vantail | B25: Fenêtre OF 1 vantail | C25: 400 – 1300 | D25: 550 – 2500
A26: Fenêtre/Porte-fenêtre OF 2 vantaux | B26: Fenêtre OF 2 vantaux | C26: 700 – 2400 | D26: 550 – 2500
A27: Fenêtre/Porte-fenêtre OB 1 vantail | B27: Fenêtre OB 1 vantail | C27: 400 – 1300 | D27: 550 – 2500
A28: Fenêtre/Porte-fenêtre OB 2 vantaux | B28: Fenêtre OB 2 vantaux | C28: 700 – 2400 | D28: 550 – 2500
A30: OPTIONS & VITRAGES
A31: Catalogue Doubles Vitrages | B31: Doubles Vitrages | C31: 6 catégories | D31: Plus-value €
A32: Options sur dormant
A33: Teintes & Finitions (RAL) | B33: Teintes & Finitions | C33: 8 familles | D33: + % menuiserie + forfait
A36: PLUS-VALUES TRAVERSES & MENEAUX (prix moyens nets HT, remise appliquée)
A37: Gamme | B37: Profilé | C37: Unité | D37: Prix moyen net HT
A38: Châssis fixe vitré | B38: Traverse 70 mm | C38: €/ml | D38: =224.46*(1-Paramètres!$B$2) -> 108.8631
A39: Châssis fixe vitré | B39: Traverse 100 mm | C39: €/ml | D39: =264.82*(1-Paramètres!$B$2) -> 128.4377
A40: Châssis fixe vitré | B40: Meneau 70 mm | C40: €/ml | D40: =230*(1-Paramètres!$B$2) -> 111.55
A41: Châssis fixe vitré | B41: Meneau 100 mm | C41: €/ml | D41: =252.73*(1-Paramètres!$B$2) -> 122.57405
A42: Fenêtre OF 1 vantail | B42: Traverse 70 mm | C42: €/ml | D42: =170.1*(1-Paramètres!$B$2) -> 82.4985
A43: Fenêtre OF 2 vantaux | B43: Traverse 70 mm | C43: €/ml | D43: =328.28*(1-Paramètres!$B$2) -> 159.2158
A44: Porte Lourde 1 vantail | B44: Traverse 70 mm | C44: €/ml | D44: =184.33*(1-Paramètres!$B$2) -> 89.40005
A45: Porte Lourde 1 vantail | B45: Traverse 100 mm | C45: €/ml | D45: =211.33*(1-Paramètres!$B$2) -> 102.49505
A46: Porte Lourde 1 vantail
A47: Porte Lourde 1 vantail | B47: Meneau 70 mm | C47: €/ml | D47: =280.71*(1-Paramètres!$B$2) -> 136.14435
...

Sheet Devis
A1: #VALUE! | F1: DEVIS - FOURNITURE SEULE - MENUISERIES ALUMINIUM
A7: INFORMATIONS CHANTIER | G7: PERFORMANCES | M7: DEMANDEUR
A8: Nom du chantier : | G8: Performance Thermique Uw : | M8: Demande émise par : | O8: Bruno ROBEIL
A9: Adresse : | G9: Facteur solaire Sw : | M9: Société : | O9: A.R.C ALUMINIUM
A10: Référence affaire : | G10: Affaiblissement acoustique : | M10: Téléphone : | O10: +33 (0)4 76 55 09 64
A11: Date de la demande : | C11: =TODAY() -> 46193 | G11: AEV : | M11: E-mail : | O11: contact@arc-alu.fr
A13: N° | B13: Localisation | C13: Type de menuiserie | D13: Famille couleur | E13: Vitrage | F13: Type de dormant | G13: Largeur (mm) | H13: Hauteur (mm) | I13: Qté | J13: Commentaires position | K13: Observations | L13: Grille de ventilation | M13: Option T/M 1 | N13: Option T/M 2 | O13: Option T/M 3 | P13: Habillage extérieur | Q13: Bavette | R13: Option porte (uniquement si Porte Lourde) | S13: Prix unitaire net HT | T13: Prix total net HT | V13: Tarif baie | W13: PV 4pts | X13: PV coul. | Y13: Forfait | Z13: PV vitr. | AA13: PV €/ml | AB13: PV % baie | AC13: PV option | AD13: PV T/M | AE13: Err T/M | AF13: T1 | AG13: T2 | AH13: T3 | AI13: M1 | AJ13: M2 | AK13: M3 | AL13: Ligne T | AM13: Ligne M
A14: 1 | C14: Coulissant 2 vantaux 2 rails | D14: Famille 1 Monocolore | E14: 4 /20/ 4 (Fe Argon WE) Clair | F14: Standard (sans doublage) | G14: 1800 | H14: 1200 | I14: 1 | J14: =IF($C14="","",$C14&" aluminium"&IF(OR($G14="",$H14=""),"",", "&$G14&" × "&$H14&" mm")&IF(OR(AND($G14<>"",IFERROR(VLOOKUP($C14,[1]_Données!$A$196:$E$211,2,FALSE()),"")<>"",OR($G14<IFERROR(VLOOKUP($C14,[1]_Données!$A$196:$E$211,2,FALSE()),""),$G14>IFERROR(VLOOKUP($C14,[1]_Données!$A$196:$E$211,3,FALSE()),""))),AND($H14<>"",IFERROR(VLOOKUP($C14,[1]_Données!$A$196:$E$211,4,FALSE()),"")<>"",OR($H14<IFERROR(VLOOKUP($C14,[1]_Données!$A$196:$E$211,4,FALSE()),""),$H14>IFERROR(VLOOKUP($C14,[1]_Données!$A$196:$E$211,5,FALSE()),"")))),CHAR(10)&"⚠ Hors abaque (L "&IFERROR(VLOOKUP($C14,[1]_Données!$A$196:$E$211,2,FALSE()),"")&"–"&IFERROR(VLOOKUP($C14,[1]_Données!$A$196:$E$211,3,FALSE()),"")&" / H "&IFERROR(VLOOKUP($C14,[1]_Données!$A$196:$E$211,4,FALSE()),"")&"–"&IFERROR(VLOOKUP($C14,[1]_Données!$A$196:$E$211,5,FALSE()),"")&" mm)","")&IF(IFERROR(VLOOKUP($C14,[1]_Données!$A$158:$B$173,2,FALSE()),"")="","",CHAR(10)&"Système : "&VLOOKUP($C14,[1]_Données!$A$158:$B$173,2,FALSE()))&IF($D14="","",CHAR(10)&"Traitement surface : "&$D14)&IF($E14="","",CHAR(10)&"Vitrage : "&$E14)&IF($F14="","",CHAR(10)&"Cadre : "&$F14)&IF(OR(IFERROR(VLOOKUP($C14,[1]_Données!$A$177:$C$192,2,FALSE()),"")="",AND(OR($C14="Porte Lourde 1 vantail",$C14="Porte Lourde 2 vantaux"),OR(ISNUMBER(SEARCH("ventouse",$R14)),ISNUMBER(SEARCH("antipanique",$R14))))),"",CHAR(10)&"Poignée : "&IFERROR(VLOOKUP($C14,[1]_Données!$A$177:$C$192,2,FALSE()),""))&IF(OR(IFERROR(VLOOKUP($C14,[1]_Données!$A$177:$C$192,3,FALSE()),"")="",AND(OR($C14="Porte Lourde 1 vantail",$C14="Porte Lourde 2 vantaux"),OR(ISNUMBER(SEARCH("ventouse",$R14)),ISNUMBER(SEARCH("antipanique",$R14))))),"",CHAR(10)&"Fermeture : "&IFERROR(VLOOKUP($C14,[1]_Données!$A$177:$C$192,3,FALSE()),""))&AL14&AM14&IF(AND($R14<>"",$R14<>"Aucune option"),CHAR(10)&"Option : "&$R14,"")&IF($L14="OUI",CHAR(10)&"Grille de ventilation","")&IF(AND($P14<>"",$P14<>"Aucun"),CHAR(10)&"Habillage extérieur : "&$P14,"")&IF(AND($Q14<>"",$Q14<>"Aucune"),CHAR(10)&"Bavette : "&$Q14,"")) -> Coulissant 2 vantaux 2 rails aluminium, 1800 × 1200 mm Système : Aluk Group 67CL32 Traitement surface : Famille 1 Monocolore Vitrage : 4 /20/ 4 (Fe Argon WE) Clair Cadre : Standard (sans doublage) Poignée : SARENA 20° sur vantail principal / Cuvette sur vantail secondaire Fermeture : Serrure multipoints Slidelock Grille de ventilation Habillage extérieur : Cornière 60×30 Bavette : Bavette 74 mm (N99987) | L14: OUI | P14: Cornière 60×30 | Q14: Bavette 74 mm (N99987) | S14: =IFERROR(IF(ISNUMBER(IFERROR(IF(ISNUMBER(IF(IFERROR(OR(AND($G14<>"",IFERROR(VLOOKUP($C14,_Données!$A$196:$E$211,2,FALSE()),"")<>"",OR($G14<VLOOKUP($C14,_Données!$A$196:$E$211,2,FALSE()),$G14>VLOOKUP($C14,_Données!$A$196:$E$211,3,FALSE()))),AND($H14<>"",IFERROR(VLOOKUP($C14,_Données!$A$196:$E$211,4,FALSE()),"")<>"",OR($H14<VLOOKUP($C14,_Données!$A$196:$E$211,4,FALSE()),$H14>VLOOKUP($C14,_Données!$A$196:$E$211,5,FALSE())))),FALSE),"",IFERROR(IF(AND($R14<>"",$R14<>"Aucune option",NOT(OR($C14="Porte Lourde 1 vantail",$C14="Porte Lourde 2 vantaux"))),"⚠ Option valable uniquement pour Porte Lourde",IF(AE14>0,"⚠ Option T/M incompatible avec la gamme",IF(V14=0,IF(AC14>0,AC14,""),IF(V14=-1,"⚠ Dimension non disponible",(V14+W14+X14+Z14+AA14+AB14+AD14)*(1-Paramètres!$B$2)+AC14)))),""))),IF(IFERROR(OR(AND($G14<>"",IFERROR(VLOOKUP($C14,_Données!$A$196:$E$211,2,FALSE()),"")<>"",OR($G14<VLOOKUP($C14,_Données!$A$196:$E$211,2,FALSE()),$G14>VLOOKUP($C14,_Données!$A$196:$E$211,3,FALSE()))),AND($H14<>"",IFERROR(VLOOKUP($C14,_Données!$A$196:$E$211,4,FALSE()),"")<>"",OR($H14<VLOOKUP($C14,_Données!$A$196:$E$211,4,FALSE()),$H14>VLOOKUP($C14,_Données!$A$196:$E$211,5,FALSE())))),FALSE),"",IFERROR(IF(AND($R14<>"",$R14<>"Aucune option",NOT(OR($C14="Porte Lourde 1 vantail",$C14="Porte Lourde 2 vantaux"))),"⚠ Option valable uniquement pour Porte Lourde",IF(AE14>0,"⚠ Option T/M incompatible avec la gamme",IF(V14=0,IF(AC14>0,AC14,""),IF(V14=-1,"⚠ Dimension non disponible",(V14+W14+X14+Z14+AA14+AB14+AD14)*(1-Paramètres!$B$2)+AC14)))),""))+IF($L14="OUI",25,0),IF(IFERROR(OR(AND($G14<>"",IFERROR(VLOOKUP($C14,_Données!$A$196:$E$211,2,FALSE()),"")<>"",OR($G14<VLOOKUP($C14,_Données!$A$196:$E$211,2,FALSE()),$G14>VLOOKUP($C14,_Données!$A$196:$E$211,3,FALSE()))),AND($H14<>"",IFERROR(VLOOKUP($C14,_Données!$A$196:$E$211,4,FALSE()),"")<>"",OR($H14<VLOOKUP($C14,_Données!$A$196:$E$211,4,FALSE()),$H14>VLOOKUP($C14,_Données!$A$196:$E$211,5,FALSE())))),FALSE),"",IFERROR(IF(AND($R14<>"",$R14<>"Aucune option",NOT(OR($C14="Porte Lourde 1 vantail",$C14="Porte Lourde 2 vantaux"))),"⚠ Option valable uniquement pour Porte Lourde",IF(AE14>0,"⚠ Option T/M incompatible avec la gamme",IF(V14=0,IF(AC14>0,AC14,""),IF(V14=-1,"⚠ Dimension non disponible",(V14+W14+X14+Z14+AA14+AB14+AD14)*(1-Paramètres!$B$2)+AC14)))),""))),"")),IFERROR(IF(ISNUMBER(IF(IFERROR(OR(AND($G14<>"",IFERROR(VLOOKUP($C14,_Données!$A$196:$E$211,2,FALSE()),"")<>"",OR($G14<VLOOKUP($C14,_Données!$A$196:$E$211,2,FALSE()),$G14>VLOOKUP($C14,_Données!$A$196:$E$211,3,FALSE()))),AND($H14<>"",IFERROR(VLOOKUP($C14,_Données!$A$196:$E$211,4,FALSE()),"")<>"",OR($H14<VLOOKUP($C14,_Données!$A$196:$E$211,4,FALSE()),$H14>VLOOKUP($C14,_Données!$A$196:$E$211,5,FALSE())))),FALSE),"",IFERROR(IF(AND($R14<>"",$R14<>"Aucune option",NOT(OR($C14="Porte Lourde 1 vantail",$C14="Porte Lourde 2 vantaux"))),"⚠ Option valable uniquement pour Porte Lourde",IF(AE14>0,"⚠ Option T/M incompatible avec la gamme",IF(V14=0,IF(AC14>0,AC14,""),IF(V14=-1,"⚠ Dimension non disponible",(V14+W14+X14+Z14+AA14+AB14+AD14)*(1-Paramètres!$B$2)+AC14)))),""))),IF(IFERROR(OR(AND($G14<>"",IFERROR(VLOOKUP($C14,_Données!$A$196:$E$211,2,FALSE()),"")<>"",OR($G14<VLOOKUP($C14,_Données!$A$196:$E$211,2,FALSE()),$G14>VLOOKUP($C14,_Données!$A$196:$E$211,3,FALSE()))),AND($H14<>"",IFERROR(VLOOKUP($C14,_Données!$A$196:$E$211,4,FALSE()),"")<>"",OR($H14<VLOOKUP($C14,_Données!$A$196:$E$211,4,FALSE()),$H14>VLOOKUP($C14,_Données!$A$196:$E$211,5,FALSE())))),FALSE),"",IFERROR(IF(AND($R14<>"",$R14<>"Aucune option",NOT(OR($C14="Porte Lourde 1 vantail",$C14="Porte Lourde 2 vantaux"))),"⚠ Option valable uniquement pour Porte Lourde",IF(AE14>0,"⚠ Option T/M incompatible avec la gamme",IF(V14=0,IF(AC14>0,AC14,""),IF(V14=-1,"⚠ Dimension non disponible",(V14+W14+X14+Z14+AA14+AB14+AD14)*(1-Paramètres!$B$2)+AC14)))),""))+IF($L14="OUI",25,0),IF(IFERROR(OR(AND($G14<>"",IFERROR(VLOOKUP($C14,_Données!$A$196:$E$211,2,FALSE()),"")<>"",OR($G14<VLOOKUP($C14,_Données!$A$196:$E$211,2,FALSE()),$G14>VLOOKUP($C14,_Données!$A$196:$E$211,3,FALSE()))),AND($H14<>"",IFERROR(VLOOKUP($C14,_Données!$A$196:$E$211,4,FALSE()),"")<>"",OR($H14<VLOOKUP($C14,_Données!$A$196:$E$211,4,FALSE()),$H14>VLOOKUP($C14,_Données!$A$196:$E$211,5,FALSE())))),FALSE),"",IFERROR(IF(AND($R14<>"",$R14<>"Aucune option",NOT(OR($C14="Porte Lourde 1 vantail",$C14="Porte Lourde 2 vantaux"))),"⚠ Option valable uniquement pour Porte Lourde",IF(AE14>0,"⚠ Option T/M incompatible avec la gamme",IF(V14=0,IF(AC14>0,AC14,""),IF(V14=-1,"⚠ Dimension non disponible",(V14+W14+X14+Z14+AA14+AB14+AD14)*(1-Paramètres!$B$2)+AC14)))),""))),"")+IFERROR(VLOOKUP($P14,_Données!$A$218:$B$229,2,FALSE())*($G14+2*$H14)/1000,0)+IFERROR(VLOOKUP($Q14,_Données!$A$232:$B$236,2,FALSE())*$G14/1000,0),IFERROR(IF(ISNUMBER(IF(IFERROR(OR(AND($G14<>"",IFERROR(VLOOKUP($C14,_Données!$A$196:$E$211,2,FALSE()),"")<>"",OR($G14<VLOOKUP($C14,_Données!$A$196:$E$211,2,FALSE()),$G14>VLOOKUP($C14,_Données!$A$196:$E$211,3,FALSE()))),AND($H14<>"",IFERROR(VLOOKUP($C14,_Données!$A$196:$E$211,4,FALSE()),"")<>"",OR($H14<VLOOKUP($C14,_Données!$A$196:$E$211,4,FALSE()),$H14>VLOOKUP($C14,_Données!$A$196:$E$211,5,FALSE())))),FALSE),"",IFERROR(IF(AND($R14<>"",$R14<>"Aucune option",NOT(OR($C14="Porte Lourde 1 vantail",$C14="Porte Lourde 2 vantaux"))),"⚠ Option valable uniquement pour Porte Lourde",IF(AE14>0,"⚠ Option T/M incompatible avec la gamme",IF(V14=0,IF(AC14>0,AC14,""),IF(V14=-1,"⚠ Dimension non disponible",(V14+W14+X14+Z14+AA14+AB14+AD14)*(1-Paramètres!$B$2)+AC14)))),""))),IF(IFERROR(OR(AND($G14<>"",IFERROR(VLOOKUP($C14,_Données!$A$196:$E$211,2,FALSE()),"")<>"",OR($G14<VLOOKUP($C14,_Données!$A$196:$E$211,2,FALSE()),$G14>VLOOKUP($C14,_Données!$A$196:$E$211,3,FALSE()))),AND($H14<>"",IFERROR(VLOOKUP($C14,_Données!$A$196:$E$211,4,FALSE()),"")<>"",OR($H14<VLOOKUP($C14,_Données!$A$196:$E$211,4,FALSE()),$H14>VLOOKUP($C14,_Données!$A$196:$E$211,5,FALSE())))),FALSE),"",IFERROR(IF(AND($R14<>"",$R14<>"Aucune option",NOT(OR($C14="Porte Lourde 1 vantail",$C14="Porte Lourde 2 vantaux"))),"⚠ Option valable uniquement pour Porte Lourde",IF(AE14>0,"⚠ Option T/M incompatible avec la gamme",IF(V14=0,IF(AC14>0,AC14,""),IF(V14=-1,"⚠ Dimension non disponible",(V14+W14+X14+Z14+AA14+AB14+AD14)*(1-Paramètres!$B$2)+AC14)))),""))+IF($L14="OUI",25,0),IF(IFERROR(OR(AND($G14<>"",IFERROR(VLOOKUP($C14,_Données!$A$196:$E$211,2,FALSE()),"")<>"",OR($G14<VLOOKUP($C14,_Données!$A$196:$E$211,2,FALSE()),$G14>VLOOKUP($C14,_Données!$A$196:$E$211,3,FALSE()))),AND($H14<>"",IFERROR(VLOOKUP($C14,_Données!$A$196:$E$211,4,FALSE()),"")<>"",OR($H14<VLOOKUP($C14,_Données!$A$196:$E$211,4,FALSE()),$H14>VLOOKUP($C14,_Données!$A$196:$E$211,5,FALSE())))),FALSE),"",IFERROR(IF(AND($R14<>"",$R14<>"Aucune option",NOT(OR($C14="Porte Lourde 1 vantail",$C14="Porte Lourde 2 vantaux"))),"⚠ Option valable uniquement pour Porte Lourde",IF(AE14>0,"⚠ Option T/M incompatible avec la gamme",IF(V14=0,IF(AC14>0,AC14,""),IF(V14=-1,"⚠ Dimension non disponible",(V14+W14+X14+Z14+AA14+AB14+AD14)*(1-Paramètres!$B$2)+AC14)))),""))),"")),"") -> 1198.931 | T14: =IFERROR(IF(OR(S14="",ISTEXT(S14)),"",S14*$I14),"") -> 1198.931 | V14: =IFERROR(IF(OR($C14="",$G14="",$H14=""),0,IF(INDIRECT("'"&VLOOKUP($C14,_Données!$A$3:$V$18,2,FALSE())&"'!"&ADDRESS((VLOOKUP($C14,_Données!$A$3:$V$18,12,FALSE())+IFERROR(MATCH(MAX(VLOOKUP($C14,_Données!$A$3:$V$18,18,FALSE()),MIN(VLOOKUP($C14,_Données!$A$3:$V$18,6,FALSE()),(VLOOKUP($C14,_Données!$A$3:$V$18,18,FALSE())+ROUND(($H14-VLOOKUP($C14,_Données!$A$3:$V$18,18,FALSE()))/VLOOKUP($C14,_Données!$A$3:$V$18,19,FALSE()),0)*VLOOKUP($C14,_Données!$A$3:$V$18,19,FALSE())))),INDIRECT("'"&VLOOKUP($C14,_Données!$A$3:$V$18,2,FALSE())&"'!"&ADDRESS(VLOOKUP($C14,_Données!$A$3:$V$18,12,FALSE()),1,4)&":"&ADDRESS(VLOOKUP($C14,_Données!$A$3:$V$18,12,FALSE())+VLOOKUP($C14,_Données!$A$3:$V$18,15,FALSE())-1,1,4)),0),MATCH(MAX(VLOOKUP($C14,_Données!$A$3:$V$18,18,FALSE()),MIN(VLOOKUP($C14,_Données!$A$3:$V$18,6,FALSE()),(VLOOKUP($C14,_Données!$A$3:$V$18,18,FALSE())+ROUND(($H14-VLOOKUP($C14,_Données!$A$3:$V$18,18,FALSE()))/VLOOKUP($C14,_Données!$A$3:$V$18,19,FALSE()),0)*VLOOKUP($C14,_Données!$A$3:$V$18,19,FALSE())))),INDIRECT("'"&VLOOKUP($C14,_Données!$A$3:$V$18,2,FALSE())&"'!"&ADDRESS(VLOOKUP($C14,_Données!$A$3:$V$18,12,FALSE()),1,4)&":"&ADDRESS(VLOOKUP($C14,_Données!$A$3:$V$18,12,FALSE())+VLOOKUP($C14,_Données!$A$3:$V$18,15,FALSE())-1,1,4)),1))-1),(VLOOKUP($C14,_Données!$A$3:$V$18,13,FALSE())+IFERROR(MATCH(MAX(VLOOKUP($C14,_Données!$A$3:$V$18,16,FALSE()),MIN(VLOOKUP($C14,_Données!$A$3:$V$18,4,FALSE()),(VLOOKUP($C14,_Données!$A$3:$V$18,16,FALSE())+ROUND(($G14-VLOOKUP($C14,_Données!$A$3:$V$18,16,FALSE()))/VLOOKUP($C14,_Données!$A$3:$V$18,17,FALSE()),0)*VLOOKUP($C14,_Données!$A$3:$V$18,17,FALSE())))),INDIRECT("'"&VLOOKUP($C14,_Données!$A$3:$V$18,2,FALSE())&"'!"&ADDRESS(VLOOKUP($C14,_Données!$A$3:$V$18,12,FALSE())-1,VLOOKUP($C14,_Données!$A$3:$V$18,13,FALSE()),4)&":"&ADDRESS(VLOOKUP($C14,_Données!$A$3:$V$18,12,FALSE())-1,VLOOKUP($C14,_Données!$A$3:$V$18,13,FALSE())+VLOOKUP($C14,_Données!$A$3:$V$18,14,FALSE())-1,4)),0),MATCH(MAX(VLOOKUP($C14,_Données!$A$3:$V$18,16,FALSE()),MIN(VLOOKUP($C14,_Données!$A$3:$V$18,4,FALSE()),(VLOOKUP($C14,_Données!$A$3:$V$18,16,FALSE())+ROUND(($G14-VLOOKUP($C14,_Données!$A$3:$V$18,16,FALSE()))/VLOOKUP($C14,_Données!$A$3:$V$18,17,FALSE()),0)*VLOOKUP($C14,_Données!$A$3:$V$18,17,FALSE())))),INDIRECT("'"&VLOOKUP($C14,_Données!$A$3:$V$18,2,FALSE())&"'!"&ADDRESS(VLOOKUP($C14,_Données!$A$3:$V$18,12,FALSE())-1,VLOOKUP($C14,_Données!$A$3:$V$18,13,FALSE()),4)&":"&ADDRESS(VLOOKUP($C14,_Données!$A$3:$V$18,12,FALSE())-1,VLOOKUP($C14,_Données!$A$3:$V$18,13,FALSE())+VLOOKUP($C14,_Données!$A$3:$V$18,14,FALSE())-1,4)),1))-1),4))="",-1,INDIRECT("'"&VLOOKUP($C14,_Données!$A$3:$V$18,2,FALSE())&"'!"&ADDRESS((VLOOKUP($C14,_Données!$A$3:$V$18,12,FALSE())+IFERROR(MATCH(MAX(VLOOKUP($C14,_Données!$A$3:$V$18,18,FALSE()),MIN(VLOOKUP($C14,_Données!$A$3:$V$18,6,FALSE()),(VLOOKUP($C14,_Données!$A$3:$V$18,18,FALSE())+ROUND(($H14-VLOOKUP($C14,_Données!$A$3:$V$18,18,FALSE()))/VLOOKUP($C14,_Données!$A$3:$V$18,19,FALSE()),0)*VLOOKUP($C14,_Données!$A$3:$V$18,19,FALSE())))),INDIRECT("'"&VLOOKUP($C14,_Données!$A$3:$V$18,2,FALSE())&"'!"&ADDRESS(VLOOKUP($C14,_Données!$A$3:$V$18,12,FALSE()),1,4)&":"&ADDRESS(VLOOKUP($C14,_Données!$A$3:$V$18,12,FALSE())+VLOOKUP($C14,_Données!$A$3:$V$18,15,FALSE())-1,1,4)),0),MATCH(MAX(VLOOKUP($C14,_Données!$A$3:$V$18,18,FALSE()),MIN(VLOOKUP($C14,_Données!$A$3:$V$18,6,FALSE()),(VLOOKUP($C14,_Données!$A$3:$V$18,18,FALSE())+ROUND(($H14-VLOOKUP($C14,_Données!$A$3:$V$18,18,FALSE()))/VLOOKUP($C14,_Données!$A$3:$V$18,19,FALSE()),0)*VLOOKUP($C14,_Données!$A$3:$V$18,19,FALSE())))),INDIRECT("'"&VLOOKUP($C14,_Données!$A$3:$V$18,2,FALSE())&"'!"&ADDRESS(VLOOKUP($C14,_Données!$A$3:$V$18,12,FALSE()),1,4)&":"&ADDRESS(VLOOKUP($C14,_Données!$A$3:$V$18,12,FALSE())+VLOOKUP($C14,_Données!$A$3:$V$18,15,FALSE())-1,1,4)),1))-1),(VLOOKUP($C14,_Données!$A$3:$V$18,13,FALSE())+IFERROR(MATCH(MAX(VLOOKUP($C14,_Données!$A$3:$V$18,16,FALSE()),MIN(VLOOKUP($C14,_Données!$A$3:$V$18,4,FALSE()),(VLOOKUP($C14,_Données!$A$3:$V$18,16,FALSE())+ROUND(($G14-VLOOKUP($C14,_Données!$A$3:$V$18,16,FALSE()))/VLOOKUP($C14,_Données!$A$3:$V$18,17,FALSE()),0)*VLOOKUP($C14,_Données!$A$3:$V$18,17,FALSE())))),INDIRECT("'"&VLOOKUP($C14,_Données!$A$3:$V$18,2,FALSE())&"'!"&ADDRESS(VLOOKUP($C14,_Données!$A$3:$V$18,12,FALSE())-1,VLOOKUP($C14,_Données!$A$3:$V$18,13,FALSE()),4)&":"&ADDRESS(VLOOKUP($C14,_Données!$A$3:$V$18,12,FALSE())-1,VLOOKUP($C14,_Données!$A$3:$V$18,13,FALSE())+VLOOKUP($C14,_Données!$A$3:$V$18,14,FALSE())-1,4)),0),MATCH(MAX(VLOOKUP($C14,_Données!$A$3:$V$18,16,FALSE()),MIN(VLOOKUP($C14,_Données!$A$3:$V$18,4,FALSE()),(VLOOKUP($C14,_Données!$A$3:$V$18,16,FALSE())+ROUND(($G14-VLOOKUP($C14,_Données!$A$3:$V$18,16,FALSE()))/VLOOKUP($C14,_Données!$A$3:$V$18,17,FALSE()),0)*VLOOKUP($C14,_Données!$A$3:$V$18,17,FALSE())))),INDIRECT("'"&VLOOKUP($C14,_Données!$A$3:$V$18,2,FALSE())&"'!"&ADDRESS(VLOOKUP($C14,_Données!$A$3:$V$18,12,FALSE())-1,VLOOKUP($C14,_Données!$A$3:$V$18,13,FALSE()),4)&":"&ADDRESS(VLOOKUP($C14,_Données!$A$3:$V$18,12,FALSE())-1,VLOOKUP($C14,_Données!$A$3:$V$18,13,FALSE())+VLOOKUP($C14,_Données!$A$3:$V$18,14,FALSE())-1,4)),1))-1),4)))),0) -> 1997 | W14: =IFERROR(IF(V14=0,0,IF(MAX(VLOOKUP($C14,_Données!$A$3:$V$18,18,FALSE()),MIN(VLOOKUP($C14,_Données!$A$3:$V$18,6,FALSE()),(VLOOKUP($C14,_Données!$A$3:$V$18,18,FALSE())+ROUND(($H14-VLOOKUP($C14,_Données!$A$3:$V$18,18,FALSE()))/VLOOKUP($C14,_Données!$A$3:$V$18,19,FALSE()),0)*VLOOKUP($C14,_Données!$A$3:$V$18,19,FALSE()))))>=VLOOKUP($C14,_Données!$A$3:$V$18,10,FALSE()),V14*VLOOKUP($C14,_Données!$A$3:$V$18,11,FALSE()),0)),0) -> 0 | X14: =IFERROR(IF(OR($D14="",V14=0),0,V14*VLOOKUP($D14,_Données!$A$21:$C$28,2,FALSE())),0) -> 0 | Y14: =IFERROR(IF($D14="",0,VLOOKUP($D14,_Données!$A$21:$C$28,3,FALSE())),0) -> 0 | Z14: =IFERROR(IF($E14="",0,VLOOKUP($E14,_Données!$A$48:$C$104,2,FALSE())),0) -> 0 | AA14: =IFERROR(IF(OR($F14="",$G14="",$H14=""),0,VLOOKUP($F14,_Données!$A$33:$C$43,2,FALSE())*2*($G14+$H14)/1000),0) -> 0 | AB14: =IFERROR(IF(OR($F14="",V14=0),0,V14*VLOOKUP($F14,_Données!$A$33:$C$43,3,FALSE())),0) -> 0 | AC14: =IFERROR(IF(OR($R14="",$R14="Aucune option",NOT(OR($C14="Porte Lourde 1 vantail",$C14="Porte Lourde 2 vantaux"))),0,VLOOKUP($R14,_Données!$A$109:$C$125,2,FALSE())*0.75*IF(VLOOKUP($R14,_Données!$A$109:$C$125,3,FALSE())=1,IF($C14="Porte Lourde 1 vantail",1,IF($C14="Porte Lourde 2 vantaux",2,1)),1)*(1-Paramètres!$B$2)),0) -> 0 | AD14: =IFERROR(IF(OR($M14="",$M14="Aucune"),0,VLOOKUP($C14&"|"&$M14,_Données!$A$132:$B$146,2,FALSE())*IF(LEFT($M14,8)="Traverse",$G14,$H14)/1000),0)+IFERROR(IF(OR($N14="",$N14="Aucune"),0,VLOOKUP($C14&"|"&$N14,_Données!$A$132:$B$146,2,FALSE())*IF(LEFT($N14,8)="Traverse",$G14,$H14)/1000),0)+IFERROR(IF(OR($O14="",$O14="Aucune"),0,VLOOKUP($C14&"|"&$O14,_Données!$A$132:$B$146,2,FALSE())*IF(LEFT($O14,8)="Traverse",$G14,$H14)/1000),0) -> 0 | AE14: =IF(AND($M14<>"",$M14<>"Aucune"),IF(ISNA(VLOOKUP($C14&"|"&$M14,_Données!$A$132:$B$146,2,FALSE())),1,0),0)+IF(AND($N14<>"",$N14<>"Aucune"),IF(ISNA(VLOOKUP($C14&"|"&$N14,_Données!$A$132:$B$146,2,FALSE())),1,0),0)+IF(AND($O14<>"",$O14<>"Aucune"),IF(ISNA(VLOOKUP($C14&"|"&$O14,_Données!$A$132:$B$146,2,FALSE())),1,0),0) -> 0 | AF14: =IF(LEFT($M14,8)="Traverse",$M14,"") | AG14: =IF(LEFT($N14,8)="Traverse",$N14,"") | AH14: =IF(LEFT($O14,8)="Traverse",$O14,"") | AI14: =IF(LEFT($M14,6)="Meneau",$M14,"") | AJ14: =IF(LEFT($N14,6)="Meneau",$N14,"") | AK14: =IF(LEFT($O14,6)="Meneau",$O14,"") | AL14: =IF(AND(AF14="",AG14="",AH14=""),"",CHAR(10)&"Traverses : "&AF14&IF(AND(AF14<>"",AG14<>""),", ","")&AG14&IF(AND(OR(AF14<>"",AG14<>""),AH14<>""),", ","")&AH14) | AM14: =IF(AND(AI14="",AJ14="",AK14=""),"",CHAR(10)&"Meneaux : "&AI14&IF(AND(AI14<>"",AJ14<>""),", ","")&AJ14&IF(AND(OR(AI14<>"",AJ14<>""),AK14<>""),", ","")&AK14)
A15: 2 | S15: =IFERROR(IF(ISNUMBER(IFERROR(IF(ISNUMBER(IF(IFERROR(OR(AND($G15<>"",IFERROR(VLOOKUP($C15,_Données!$A$196:$E$211,2,FALSE()),"")<>"",OR($G15<VLOOKUP($C15,_Données!$A$196:$E$211,2,FALSE()),$G15>VLOOKUP($C15,_Données!$A$196:$E$211,3,FALSE()))),AND($H15<>"",IFERROR(VLOOKUP($C15,_Données!$A$196:$E$211,4,FALSE()),"")<>"",OR($H15<VLOOKUP($C15,_Données!$A$196:$E$211,4,FALSE()),$H15>VLOOKUP($C15,_Données!$A$196:$E$211,5,FALSE())))),FALSE),"",IFERROR(IF(AND($R15<>"",$R15<>"Aucune option",NOT(OR($C15="Porte Lourde 1 vantail",$C15="Porte Lourde 2 vantaux"))),"⚠ Option valable uniquement pour Porte Lourde",IF(AE15>0,"⚠ Option T/M incompatible avec la gamme",IF(V15=0,IF(AC15>0,AC15,""),IF(V15=-1,"⚠ Dimension non disponible",(V15+W15+X15+Z15+AA15+AB15+AD15)*(1-Paramètres!$B$2)+AC15)))),""))),IF(IFERROR(OR(AND($G15<>"",IFERROR(VLOOKUP($C15,_Données!$A$196:$E$211,2,FALSE()),"")<>"",OR($G15<VLOOKUP($C15,_Données!$A$196:$E$211,2,FALSE()),$G15>VLOOKUP($C15,_Données!$A$196:$E$211,3,FALSE()))),AND($H15<>"",IFERROR(VLOOKUP($C15,_Données!$A$196:$E$211,4,FALSE()),"")<>"",OR($H15<VLOOKUP($C15,_Données!$A$196:$E$211,4,FALSE()),$H15>VLOOKUP($C15,_Données!$A$196:$E$211,5,FALSE())))),FALSE),"",IFERROR(IF(AND($R15<>"",$R15<>"Aucune option",NOT(OR($C15="Porte Lourde 1 vantail",$C15="Porte Lourde 2 vantaux"))),"⚠ Option valable uniquement pour Porte Lourde",IF(AE15>0,"⚠ Option T/M incompatible avec la gamme",IF(V15=0,IF(AC15>0,AC15,""),IF(V15=-1,"⚠ Dimension non disponible",(V15+W15+X15+Z15+AA15+AB15+AD15)*(1-Paramètres!$B$2)+AC15)))),""))+IF($L15="OUI",25,0),IF(IFERROR(OR(AND($G15<>"",IFERROR(VLOOKUP($C15,_Données!$A$196:$E$211,2,FALSE()),"")<>"",OR($G15<VLOOKUP($C15,_Données!$A$196:$E$211,2,FALSE()),$G15>VLOOKUP($C15,_Données!$A$196:$E$211,3,FALSE()))),AND($H15<>"",IFERROR(VLOOKUP($C15,_Données!$A$196:$E$211,4,FALSE()),"")<>"",OR($H15<VLOOKUP($C15,_Données!$A$196:$E$211,4,FALSE()),$H15>VLOOKUP($C15,_Données!$A$196:$E$211,5,FALSE())))),FALSE),"",IFERROR(IF(AND($R15<>"",$R15<>"Aucune option",NOT(OR($C15="Porte Lourde 1 vantail",$C15="Porte Lourde 2 vantaux"))),"⚠ Option valable uniquement pour Porte Lourde",IF(AE15>0,"⚠ Option T/M incompatible avec la gamme",IF(V15=0,IF(AC15>0,AC15,""),IF(V15=-1,"⚠ Dimension non disponible",(V15+W15+X15+Z15+AA15+AB15+AD15)*(1-Paramètres!$B$2)+AC15)))),""))),"")),IFERROR(IF(ISNUMBER(IF(IFERROR(OR(AND($G15<>"",IFERROR(VLOOKUP($C15,_Données!$A$196:$E$211,2,FALSE()),"")<>"",OR($G15<VLOOKUP($C15,_Données!$A$196:$E$211,2,FALSE()),$G15>VLOOKUP($C15,_Données!$A$196:$E$211,3,FALSE()))),AND($H15<>"",IFERROR(VLOOKUP($C15,_Données!$A$196:$E$211,4,FALSE()),"")<>"",OR($H15<VLOOKUP($C15,_Données!$A$196:$E$211,4,FALSE()),$H15>VLOOKUP($C15,_Données!$A$196:$E$211,5,FALSE())))),FALSE),"",IFERROR(IF(AND($R15<>"",$R15<>"Aucune option",NOT(OR($C15="Porte Lourde 1 vantail",$C15="Porte Lourde 2 vantaux"))),"⚠ Option valable uniquement pour Porte Lourde",IF(AE15>0,"⚠ Option T/M incompatible avec la gamme",IF(V15=0,IF(AC15>0,AC15,""),IF(V15=-1,"⚠ Dimension non disponible",(V15+W15+X15+Z15+AA15+AB15+AD15)*(1-Paramètres!$B$2)+AC15)))),""))),IF(IFERROR(OR(AND($G15<>"",IFERROR(VLOOKUP($C15,_Données!$A$196:$E$211,2,FALSE()),"")<>"",OR($G15<VLOOKUP($C15,_Données!$A$196:$E$211,2,FALSE()),$G15>VLOOKUP($C15,_Données!$A$196:$E$211,3,FALSE()))),AND($H15<>"",IFERROR(VLOOKUP($C15,_Données!$A$196:$E$211,4,FALSE()),"")<>"",OR($H15<VLOOKUP($C15,_Données!$A$196:$E$211,4,FALSE()),$H15>VLOOKUP($C15,_Données!$A$196:$E$211,5,FALSE())))),FALSE),"",IFERROR(IF(AND($R15<>"",$R15<>"Aucune option",NOT(OR($C15="Porte Lourde 1 vantail",$C15="Porte Lourde 2 vantaux"))),"⚠ Option valable uniquement pour Porte Lourde",IF(AE15>0,"⚠ Option T/M incompatible avec la gamme",IF(V15=0,IF(AC15>0,AC15,""),IF(V15=-1,"⚠ Dimension non disponible",(V15+W15+X15+Z15+AA15+AB15+AD15)*(1-Paramètres!$B$2)+AC15)))),""))+IF($L15="OUI",25,0),IF(IFERROR(OR(AND($G15<>"",IFERROR(VLOOKUP($C15,_Données!$A$196:$E$211,2,FALSE()),"")<>"",OR($G15<VLOOKUP($C15,_Données!$A$196:$E$211,2,FALSE()),$G15>VLOOKUP($C15,_Données!$A$196:$E$211,3,FALSE()))),AND($H15<>"",IFERROR(VLOOKUP($C15,_Données!$A$196:$E$211,4,FALSE()),"")<>"",OR($H15<VLOOKUP($C15,_Données!$A$196:$E$211,4,FALSE()),$H15>VLOOKUP($C15,_Données!$A$196:$E$211,5,FALSE())))),FALSE),"",IFERROR(IF(AND($R15<>"",$R15<>"Aucune option",NOT(OR($C15="Porte Lourde 1 vantail",$C15="Porte Lourde 2 vantaux"))),"⚠ Option valable uniquement pour Porte Lourde",IF(AE15>0,"⚠ Option T/M incompatible avec la gamme",IF(V15=0,IF(AC15>0,AC15,""),IF(V15=-1,"⚠ Dimension non disponible",(V15+W15+X15+Z15+AA15+AB15+AD15)*(1-Paramètres!$B$2)+AC15)))),""))),"")+IFERROR(VLOOKUP($P15,_Données!$A$218:$B$229,2,FALSE())*($G15+2*$H15)/1000,0)+IFERROR(VLOOKUP($Q15,_Données!$A$232:$B$236,2,FALSE())*$G15/1000,0),IFERROR(IF(ISNUMBER(IF(IFERROR(OR(AND($G15<>"",IFERROR(VLOOKUP($C15,_Données!$A$196:$E$211,2,FALSE()),"")<>"",OR($G15<VLOOKUP($C15,_Données!$A$196:$E$211,2,FALSE()),$G15>VLOOKUP($C15,_Données!$A$196:$E$211,3,FALSE()))),AND($H15<>"",IFERROR(VLOOKUP($C15,_Données!$A$196:$E$211,4,FALSE()),"")<>"",OR($H15<VLOOKUP($C15,_Données!$A$196:$E$211,4,FALSE()),$H15>VLOOKUP($C15,_Données!$A$196:$E$211,5,FALSE())))),FALSE),"",IFERROR(IF(AND($R15<>"",$R15<>"Aucune option",NOT(OR($C15="Porte Lourde 1 vantail",$C15="Porte Lourde 2 vantaux"))),"⚠ Option valable uniquement pour Porte Lourde",IF(AE15>0,"⚠ Option T/M incompatible avec la gamme",IF(V15=0,IF(AC15>0,AC15,""),IF(V15=-1,"⚠ Dimension non disponible",(V15+W15+X15+Z15+AA15+AB15+AD15)*(1-Paramètres!$B$2)+AC15)))),""))),IF(IFERROR(OR(AND($G15<>"",IFERROR(VLOOKUP($C15,_Données!$A$196:$E$211,2,FALSE()),"")<>"",OR($G15<VLOOKUP($C15,_Données!$A$196:$E$211,2,FALSE()),$G15>VLOOKUP($C15,_Données!$A$196:$E$211,3,FALSE()))),AND($H15<>"",IFERROR(VLOOKUP($C15,_Données!$A$196:$E$211,4,FALSE()),"")<>"",OR($H15<VLOOKUP($C15,_Données!$A$196:$E$211,4,FALSE()),$H15>VLOOKUP($C15,_Données!$A$196:$E$211,5,FALSE())))),FALSE),"",IFERROR(IF(AND($R15<>"",$R15<>"Aucune option",NOT(OR($C15="Porte Lourde 1 vantail",$C15="Porte Lourde 2 vantaux"))),"⚠ Option valable uniquement pour Porte Lourde",IF(AE15>0,"⚠ Option T/M incompatible avec la gamme",IF(V15=0,IF(AC15>0,AC15,""),IF(V15=-1,"⚠ Dimension non disponible",(V15+W15+X15+Z15+AA15+AB15+AD15)*(1-Paramètres!$B$2)+AC15)))),""))+IF($L15="OUI",25,0),IF(IFERROR(OR(AND($G15<>"",IFERROR(VLOOKUP($C15,_Données!$A$196:$E$211,2,FALSE()),"")<>"",OR($G15<VLOOKUP($C15,_Données!$A$196:$E$211,2,FALSE()),$G15>VLOOKUP($C15,_Données!$A$196:$E$211,3,FALSE()))),AND($H15<>"",IFERROR(VLOOKUP($C15,_Données!$A$196:$E$211,4,FALSE()),"")<>"",OR($H15<VLOOKUP($C15,_Données!$A$196:$E$211,4,FALSE()),$H15>VLOOKUP($C15,_Données!$A$196:$E$211,5,FALSE())))),FALSE),"",IFERROR(IF(AND($R15<>"",$R15<>"Aucune option",NOT(OR($C15="Porte Lourde 1 vantail",$C15="Porte Lourde 2 vantaux"))),"⚠ Option valable uniquement pour Porte Lourde",IF(AE15>0,"⚠ Option T/M incompatible avec la gamme",IF(V15=0,IF(AC15>0,AC15,""),IF(V15=-1,"⚠ Dimension non disponible",(V15+W15+X15+Z15+AA15+AB15+AD15)*(1-Paramètres!$B$2)+AC15)))),""))),"")),"") | T15: =IFERROR(IF(OR(S15="",ISTEXT(S15)),"",S15*$I15),"") | V15: =IFERROR(IF(OR($C15="",$G15="",$H15=""),0,IF(INDIRECT("'"&VLOOKUP($C15,_Données!$A$3:$V$18,2,FALSE())&"'!"&ADDRESS((VLOOKUP($C15,_Données!$A$3:$V$18,12,FALSE())+IFERROR(MATCH(MAX(VLOOKUP($C15,_Données!$A$3:$V$18,18,FALSE()),MIN(VLOOKUP($C15,_Données!$A$3:$V$18,6,FALSE()),(VLOOKUP($C15,_Données!$A$3:$V$18,18,FALSE())+ROUND(($H15-VLOOKUP($C15,_Données!$A$3:$V$18,18,FALSE()))/VLOOKUP($C15,_Données!$A$3:$V$18,19,FALSE()),0)*VLOOKUP($C15,_Données!$A$3:$V$18,19,FALSE())))),INDIRECT("'"&VLOOKUP($C15,_Données!$A$3:$V$18,2,FALSE())&"'!"&ADDRESS(VLOOKUP($C15,_Données!$A$3:$V$18,12,FALSE()),1,4)&":"&ADDRESS(VLOOKUP($C15,_Données!$A$3:$V$18,12,FALSE())+VLOOKUP($C15,_Données!$A$3:$V$18,15,FALSE())-1,1,4)),0),MATCH(MAX(VLOOKUP($C15,_Données!$A$3:$V$18,18,FALSE()),MIN(VLOOKUP($C15,_Données!$A$3:$V$18,6,FALSE()),(VLOOKUP($C15,_Données!$A$3:$V$18,18,FALSE())+ROUND(($H15-VLOOKUP($C15,_Données!$A$3:$V$18,18,FALSE()))/VLOOKUP($C15,_Données!$A$3:$V$18,19,FALSE()),0)*VLOOKUP($C15,_Données!$A$3:$V$18,19,FALSE())))),INDIRECT("'"&VLOOKUP($C15,_Données!$A$3:$V$18,2,FALSE())&"'!"&ADDRESS(VLOOKUP($C15,_Données!$A$3:$V$18,12,FALSE()),1,4)&":"&ADDRESS(VLOOKUP($C15,_Données!$A$3:$V$18,12,FALSE())+VLOOKUP($C15,_Données!$A$3:$V$18,15,FALSE())-1,1,4)),1))-1),(VLOOKUP($C15,_Données!$A$3:$V$18,13,FALSE())+IFERROR(MATCH(MAX(VLOOKUP($C15,_Données!$A$3:$V$18,16,FALSE()),MIN(VLOOKUP($C15,_Données!$A$3:$V$18,4,FALSE()),(VLOOKUP($C15,_Données!$A$3:$V$18,16,FALSE())+ROUND(($G15-VLOOKUP($C15,_Données!$A$3:$V$18,16,FALSE()))/VLOOKUP($C15,_Données!$A$3:$V$18,17,FALSE()),0)*VLOOKUP($C15,_Données!$A$3:$V$18,17,FALSE())))),INDIRECT("'"&VLOOKUP($C15,_Données!$A$3:$V$18,2,FALSE())&"'!"&ADDRESS(VLOOKUP($C15,_Données!$A$3:$V$18,12,FALSE())-1,VLOOKUP($C15,_Données!$A$3:$V$18,13,FALSE()),4)&":"&ADDRESS(VLOOKUP($C15,_Données!$A$3:$V$18,12,FALSE())-1,VLOOKUP($C15,_Données!$A$3:$V$18,13,FALSE())+VLOOKUP($C15,_Données!$A$3:$V$18,14,FALSE())-1,4)),0),MATCH(MAX(VLOOKUP($C15,_Données!$A$3:$V$18,16,FALSE()),MIN(VLOOKUP($C15,_Données!$A$3:$V$18,4,FALSE()),(VLOOKUP($C15,_Données!$A$3:$V$18,16,FALSE())+ROUND(($G15-VLOOKUP($C15,_Données!$A$3:$V$18,16,FALSE()))/VLOOKUP($C15,_Données!$A$3:$V$18,17,FALSE()),0)*VLOOKUP($C15,_Données!$A$3:$V$18,17,FALSE())))),INDIRECT("'"&VLOOKUP($C15,_Données!$A$3:$V$18,2,FALSE())&"'!"&ADDRESS(VLOOKUP($C15,_Données!$A$3:$V$18,12,FALSE())-1,VLOOKUP($C15,_Données!$A$3:$V$18,13,FALSE()),4)&":"&ADDRESS(VLOOKUP($C15,_Données!$A$3:$V$18,12,FALSE())-1,VLOOKUP($C15,_Données!$A$3:$V$18,13,FALSE())+VLOOKUP($C15,_Données!$A$3:$V$18,14,FALSE())-1,4)),1))-1),4))="",-1,INDIRECT("'"&VLOOKUP($C15,_Données!$A$3:$V$18,2,FALSE())&"'!"&ADDRESS((VLOOKUP($C15,_Données!$A$3:$V$18,12,FALSE())+IFERROR(MATCH(MAX(VLOOKUP($C15,_Données!$A$3:$V$18,18,FALSE()),MIN(VLOOKUP($C15,_Données!$A$3:$V$18,6,FALSE()),(VLOOKUP($C15,_Données!$A$3:$V$18,18,FALSE())+ROUND(($H15-VLOOKUP($C15,_Données!$A$3:$V$18,18,FALSE()))/VLOOKUP($C15,_Données!$A$3:$V$18,19,FALSE()),0)*VLOOKUP($C15,_Données!$A$3:$V$18,19,FALSE())))),INDIRECT("'"&VLOOKUP($C15,_Données!$A$3:$V$18,2,FALSE())&"'!"&ADDRESS(VLOOKUP($C15,_Données!$A$3:$V$18,12,FALSE()),1,4)&":"&ADDRESS(VLOOKUP($C15,_Données!$A$3:$V$18,12,FALSE())+VLOOKUP($C15,_Données!$A$3:$V$18,15,FALSE())-1,1,4)),0),MATCH(MAX(VLOOKUP($C15,_Données!$A$3:$V$18,18,FALSE()),MIN(VLOOKUP($C15,_Données!$A$3:$V$18,6,FALSE()),(VLOOKUP($C15,_Données!$A$3:$V$18,18,FALSE())+ROUND(($H15-VLOOKUP($C15,_Données!$A$3:$V$18,18,FALSE()))/VLOOKUP($C15,_Données!$A$3:$V$18,19,FALSE()),0)*VLOOKUP($C15,_Données!$A$3:$V$18,19,FALSE())))),INDIRECT("'"&VLOOKUP($C15,_Données!$A$3:$V$18,2,FALSE())&"'!"&ADDRESS(VLOOKUP($C15,_Données!$A$3:$V$18,12,FALSE()),1,4)&":"&ADDRESS(VLOOKUP($C15,_Données!$A$3:$V$18,12,FALSE())+VLOOKUP($C15,_Données!$A$3:$V$18,15,FALSE())-1,1,4)),1))-1),(VLOOKUP($C15,_Données!$A$3:$V$18,13,FALSE())+IFERROR(MATCH(MAX(VLOOKUP($C15,_Données!$A$3:$V$18,16,FALSE()),MIN(VLOOKUP($C15,_Données!$A$3:$V$18,4,FALSE()),(VLOOKUP($C15,_Données!$A$3:$V$18,16,FALSE())+ROUND(($G15-VLOOKUP($C15,_Données!$A$3:$V$18,16,FALSE()))/VLOOKUP($C15,_Données!$A$3:$V$18,17,FALSE()),0)*VLOOKUP($C15,_Données!$A$3:$V$18,17,FALSE())))),INDIRECT("'"&VLOOKUP($C15,_Données!$A$3:$V$18,2,FALSE())&"'!"&ADDRESS(VLOOKUP($C15,_Données!$A$3:$V$18,12,FALSE())-1,VLOOKUP($C15,_Données!$A$3:$V$18,13,FALSE()),4)&":"&ADDRESS(VLOOKUP($C15,_Données!$A$3:$V$18,12,FALSE())-1,VLOOKUP($C15,_Données!$A$3:$V$18,13,FALSE())+VLOOKUP($C15,_Données!$A$3:$V$18,14,FALSE())-1,4)),0),MATCH(MAX(VLOOKUP($C15,_Données!$A$3:$V$18,16,FALSE()),MIN(VLOOKUP($C15,_Données!$A$3:$V$18,4,FALSE()),(VLOOKUP($C15,_Données!$A$3:$V$18,16,FALSE())+ROUND(($G15-VLOOKUP($C15,_Données!$A$3:$V$18,16,FALSE()))/VLOOKUP($C15,_Données!$A$3:$V$18,17,FALSE()),0)*VLOOKUP($C15,_Données!$A$3:$V$18,17,FALSE())))),INDIRECT("'"&VLOOKUP($C15,_Données!$A$3:$V$18,2,FALSE())&"'!"&ADDRESS(VLOOKUP($C15,_Données!$A$3:$V$18,12,FALSE())-1,VLOOKUP($C15,_Données!$A$3:$V$18,13,FALSE()),4)&":"&ADDRESS(VLOOKUP($C15,_Données!$A$3:$V$18,12,FALSE())-1,VLOOKUP($C15,_Données!$A$3:$V$18,13,FALSE())+VLOOKUP($C15,_Données!$A$3:$V$18,14,FALSE())-1,4)),1))-1),4)))),0) -> 0 | W15: =IFERROR(IF(V15=0,0,IF(MAX(VLOOKUP($C15,_Données!$A$3:$V$18,18,FALSE()),MIN(VLOOKUP($C15,_Données!$A$3:$V$18,6,FALSE()),(VLOOKUP($C15,_Données!$A$3:$V$18,18,FALSE())+ROUND(($H15-VLOOKUP($C15,_Données!$A$3:$V$18,18,FALSE()))/VLOOKUP($C15,_Données!$A$3:$V$18,19,FALSE()),0)*VLOOKUP($C15,_Données!$A$3:$V$18,19,FALSE()))))>=VLOOKUP($C15,_Données!$A$3:$V$18,10,FALSE()),V15*VLOOKUP($C15,_Données!$A$3:$V$18,11,FALSE()),0)),0) -> 0 | X15: =IFERROR(IF(OR($D15="",V15=0),0,V15*VLOOKUP($D15,_Données!$A$21:$C$28,2,FALSE())),0) -> 0 | Y15: =IFERROR(IF($D15="",0,VLOOKUP($D15,_Données!$A$21:$C$28,3,FALSE())),0) -> 0 | Z15: =IFERROR(IF($E15="",0,VLOOKUP($E15,_Données!$A$48:$C$104,2,FALSE())),0) -> 0 | AA15: =IFERROR(IF(OR($F15="",$G15="",$H15=""),0,VLOOKUP($F15,_Données!$A$33:$C$43,2,FALSE())*2*($G15+$H15)/1000),0) -> 0 | AB15: =IFERROR(IF(OR($F15="",V15=0),0,V15*VLOOKUP($F15,_Données!$A$33:$C$43,3,FALSE())),0) -> 0 | AC15: =IFERROR(IF(OR($R15="",$R15="Aucune option",NOT(OR($C15="Porte Lourde 1 vantail",$C15="Porte Lourde 2 vantaux"))),0,VLOOKUP($R15,_Données!$A$109:$C$125,2,FALSE())*0.75*IF(VLOOKUP($R15,_Données!$A$109:$C$125,3,FALSE())=1,IF($C15="Porte Lourde 1 vantail",1,IF($C15="Porte Lourde 2 vantaux",2,1)),1)*(1-Paramètres!$B$2)),0) -> 0 | AD15: =IFERROR(IF(OR($M15="",$M15="Aucune"),0,VLOOKUP($C15&"|"&$M15,_Données!$A$132:$B$146,2,FALSE())*IF(LEFT($M15,8)="Traverse",$G15,$H15)/1000),0)+IFERROR(IF(OR($N15="",$N15="Aucune"),0,VLOOKUP($C15&"|"&$N15,_Données!$A$132:$B$146,2,FALSE())*IF(LEFT($N15,8)="Traverse",$G15,$H15)/1000),0)+IFERROR(IF(OR($O15="",$O15="Aucune"),0,VLOOKUP($C15&"|"&$O15,_Données!$A$132:$B$146,2,FALSE())*IF(LEFT($O15,8)="Traverse",$G15,$H15)/1000),0) -> 0 | AE15: =IF(AND($M15<>"",$M15<>"Aucune"),IF(ISNA(VLOOKUP($C15&"|"&$M15,_Données!$A$132:$B$146,2,FALSE())),1,0),0)+IF(AND($N15<>"",$N15<>"Aucune"),IF(ISNA(VLOOKUP($C15&"|"&$N15,_Données!$A$132:$B$146,2,FALSE())),1,0),0)+IF(AND($O15<>"",$O15<>"Aucune"),IF(ISNA(VLOOKUP($C15&"|"&$O15,_Données!$A$132:$B$146,2,FALSE())),1,0),0) -> 0 | AF15: =IF(LEFT($M15,8)="Traverse",$M15,"") | AG15: =IF(LEFT($N15,8)="Traverse",$N15,"") | AH15: =IF(LEFT($O15,8)="Traverse",$O15,"") | AI15: =IF(LEFT($M15,6)="Meneau",$M15,"") | AJ15: =IF(LEFT($N15,6)="Meneau",$N15,"") | AK15: =IF(LEFT($O15,6)="Meneau",$O15,"") | AL15: =IF(AND(AF15="",AG15="",AH15=""),"",CHAR(10)&"Traverses : "&AF15&IF(AND(AF15<>"",AG15<>""),", ","")&AG15&IF(AND(OR(AF15<>"",AG15<>""),AH15<>""),", ","")&AH15) | AM15: =IF(AND(AI15="",AJ15="",AK15=""),"",CHAR(10)&"Meneaux : "&AI15&IF(AND(AI15<>"",AJ15<>""),", ","")&AJ15&IF(AND(OR(AI15<>"",AJ15<>""),AK15<>""),", ","")&AK15)
A16: 3 | S16: =IFERROR(IF(ISNUMBER(IFERROR(IF(ISNUMBER(IF(IFERROR(OR(AND($G16<>"",IFERROR(VLOOKUP($C16,_Données!$A$196:$E$211,2,FALSE()),"")<>"",OR($G16<VLOOKUP($C16,_Données!$A$196:$E$211,2,FALSE()),$G16>VLOOKUP($C16,_Données!$A$196:$E$211,3,FALSE()))),AND($H16<>"",IFERROR(VLOOKUP($C16,_Données!$A$196:$E$211,4,FALSE()),"")<>"",OR($H16<VLOOKUP($C16,_Données!$A$196:$E$211,4,FALSE()),$H16>VLOOKUP($C16,_Données!$A$196:$E$211,5,FALSE())))),FALSE),"",IFERROR(IF(AND($R16<>"",$R16<>"Aucune option",NOT(OR($C16="Porte Lourde 1 vantail",$C16="Porte Lourde 2 vantaux"))),"⚠ Option valable uniquement pour Porte Lourde",IF(AE16>0,"⚠ Option T/M incompatible avec la gamme",IF(V16=0,IF(AC16>0,AC16,""),IF(V16=-1,"⚠ Dimension non disponible",(V16+W16+X16+Z16+AA16+AB16+AD16)*(1-Paramètres!$B$2)+AC16)))),""))),IF(IFERROR(OR(AND($G16<>"",IFERROR(VLOOKUP($C16,_Données!$A$196:$E$211,2,FALSE()),"")<>"",OR($G16<VLOOKUP($C16,_Données!$A$196:$E$211,2,FALSE()),$G16>VLOOKUP($C16,_Données!$A$196:$E$211,3,FALSE()))),AND($H16<>"",IFERROR(VLOOKUP($C16,_Données!$A$196:$E$211,4,FALSE()),"")<>"",OR($H16<VLOOKUP($C16,_Données!$A$196:$E$211,4,FALSE()),$H16>VLOOKUP($C16,_Données!$A$196:$E$211,5,FALSE())))),FALSE),"",IFERROR(IF(AND($R16<>"",$R16<>"Aucune option",NOT(OR($C16="Porte Lourde 1 vantail",$C16="Porte Lourde 2 vantaux"))),"⚠ Option valable uniquement pour Porte Lourde",IF(AE16>0,"⚠ Option T/M incompatible avec la gamme",IF(V16=0,IF(AC16>0,AC16,""),IF(V16=-1,"⚠ Dimension non disponible",(V16+W16+X16+Z16+AA16+AB16+AD16)*(1-Paramètres!$B$2)+AC16)))),""))+IF($L16="OUI",25,0),IF(IFERROR(OR(AND($G16<>"",IFERROR(VLOOKUP($C16,_Données!$A$196:$E$211,2,FALSE()),"")<>"",OR($G16<VLOOKUP($C16,_Données!$A$196:$E$211,2,FALSE()),$G16>VLOOKUP($C16,_Données!$A$196:$E$211,3,FALSE()))),AND($H16<>"",IFERROR(VLOOKUP($C16,_Données!$A$196:$E$211,4,FALSE()),"")<>"",OR($H16<VLOOKUP($C16,_Données!$A$196:$E$211,4,FALSE()),$H16>VLOOKUP($C16,_Données!$A$196:$E$211,5,FALSE())))),FALSE),"",IFERROR(IF(AND($R16<>"",$R16<>"Aucune option",NOT(OR($C16="Porte Lourde 1 vantail",$C16="Porte Lourde 2 vantaux"))),"⚠ Option valable uniquement pour Porte Lourde",IF(AE16>0,"⚠ Option T/M incompatible avec la gamme",IF(V16=0,IF(AC16>0,AC16,""),IF(V16=-1,"⚠ Dimension non disponible",(V16+W16+X16+Z16+AA16+AB16+AD16)*(1-Paramètres!$B$2)+AC16)))),""))),"")),IFERROR(IF(ISNUMBER(IF(IFERROR(OR(AND($G16<>"",IFERROR(VLOOKUP($C16,_Données!$A$196:$E$211,2,FALSE()),"")<>"",OR($G16<VLOOKUP($C16,_Données!$A$196:$E$211,2,FALSE()),$G16>VLOOKUP($C16,_Données!$A$196:$E$211,3,FALSE()))),AND($H16<>"",IFERROR(VLOOKUP($C16,_Données!$A$196:$E$211,4,FALSE()),"")<>"",OR($H16<VLOOKUP($C16,_Données!$A$196:$E$211,4,FALSE()),$H16>VLOOKUP($C16,_Données!$A$196:$E$211,5,FALSE())))),FALSE),"",IFERROR(IF(AND($R16<>"",$R16<>"Aucune option",NOT(OR($C16="Porte Lourde 1 vantail",$C16="Porte Lourde 2 vantaux"))),"⚠ Option valable uniquement pour Porte Lourde",IF(AE16>0,"⚠ Option T/M incompatible avec la gamme",IF(V16=0,IF(AC16>0,AC16,""),IF(V16=-1,"⚠ Dimension non disponible",(V16+W16+X16+Z16+AA16+AB16+AD16)*(1-Paramètres!$B$2)+AC16)))),""))),IF(IFERROR(OR(AND($G16<>"",IFERROR(VLOOKUP($C16,_Données!$A$196:$E$211,2,FALSE()),"")<>"",OR($G16<VLOOKUP($C16,_Données!$A$196:$E$211,2,FALSE()),$G16>VLOOKUP($C16,_Données!$A$196:$E$211,3,FALSE()))),AND($H16<>"",IFERROR(VLOOKUP($C16,_Données!$A$196:$E$211,4,FALSE()),"")<>"",OR($H16<VLOOKUP($C16,_Données!$A$196:$E$211,4,FALSE()),$H16>VLOOKUP($C16,_Données!$A$196:$E$211,5,FALSE())))),FALSE),"",IFERROR(IF(AND($R16<>"",$R16<>"Aucune option",NOT(OR($C16="Porte Lourde 1 vantail",$C16="Porte Lourde 2 vantaux"))),"⚠ Option valable uniquement pour Porte Lourde",IF(AE16>0,"⚠ Option T/M incompatible avec la gamme",IF(V16=0,IF(AC16>0,AC16,""),IF(V16=-1,"⚠ Dimension non disponible",(V16+W16+X16+Z16+AA16+AB16+AD16)*(1-Paramètres!$B$2)+AC16)))),""))+IF($L16="OUI",25,0),IF(IFERROR(OR(AND($G16<>"",IFERROR(VLOOKUP($C16,_Données!$A$196:$E$211,2,FALSE()),"")<>"",OR($G16<VLOOKUP($C16,_Données!$A$196:$E$211,2,FALSE()),$G16>VLOOKUP($C16,_Données!$A$196:$E$211,3,FALSE()))),AND($H16<>"",IFERROR(VLOOKUP($C16,_Données!$A$196:$E$211,4,FALSE()),"")<>"",OR($H16<VLOOKUP($C16,_Données!$A$196:$E$211,4,FALSE()),$H16>VLOOKUP($C16,_Données!$A$196:$E$211,5,FALSE())))),FALSE),"",IFERROR(IF(AND($R16<>"",$R16<>"Aucune option",NOT(OR($C16="Porte Lourde 1 vantail",$C16="Porte Lourde 2 vantaux"))),"⚠ Option valable uniquement pour Porte Lourde",IF(AE16>0,"⚠ Option T/M incompatible avec la gamme",IF(V16=0,IF(AC16>0,AC16,""),IF(V16=-1,"⚠ Dimension non disponible",(V16+W16+X16+Z16+AA16+AB16+AD16)*(1-Paramètres!$B$2)+AC16)))),""))),"")+IFERROR(VLOOKUP($P16,_Données!$A$218:$B$229,2,FALSE())*($G16+2*$H16)/1000,0)+IFERROR(VLOOKUP($Q16,_Données!$A$232:$B$236,2,FALSE())*$G16/1000,0),IFERROR(IF(ISNUMBER(IF(IFERROR(OR(AND($G16<>"",IFERROR(VLOOKUP($C16,_Données!$A$196:$E$211,2,FALSE()),"")<>"",OR($G16<VLOOKUP($C16,_Données!$A$196:$E$211,2,FALSE()),$G16>VLOOKUP($C16,_Données!$A$196:$E$211,3,FALSE()))),AND($H16<>"",IFERROR(VLOOKUP($C16,_Données!$A$196:$E$211,4,FALSE()),"")<>"",OR($H16<VLOOKUP($C16,_Données!$A$196:$E$211,4,FALSE()),$H16>VLOOKUP($C16,_Données!$A$196:$E$211,5,FALSE())))),FALSE),"",IFERROR(IF(AND($R16<>"",$R16<>"Aucune option",NOT(OR($C16="Porte Lourde 1 vantail",$C16="Porte Lourde 2 vantaux"))),"⚠ Option valable uniquement pour Porte Lourde",IF(AE16>0,"⚠ Option T/M incompatible avec la gamme",IF(V16=0,IF(AC16>0,AC16,""),IF(V16=-1,"⚠ Dimension non disponible",(V16+W16+X16+Z16+AA16+AB16+AD16)*(1-Paramètres!$B$2)+AC16)))),""))),IF(IFERROR(OR(AND($G16<>"",IFERROR(VLOOKUP($C16,_Données!$A$196:$E$211,2,FALSE()),"")<>"",OR($G16<VLOOKUP($C16,_Données!$A$196:$E$211,2,FALSE()),$G16>VLOOKUP($C16,_Données!$A$196:$E$211,3,FALSE()))),AND($H16<>"",IFERROR(VLOOKUP($C16,_Données!$A$196:$E$211,4,FALSE()),"")<>"",OR($H16<VLOOKUP($C16,_Données!$A$196:$E$211,4,FALSE()),$H16>VLOOKUP($C16,_Données!$A$196:$E$211,5,FALSE())))),FALSE),"",IFERROR(IF(AND($R16<>"",$R16<>"Aucune option",NOT(OR($C16="Porte Lourde 1 vantail",$C16="Porte Lourde 2 vantaux"))),"⚠ Option valable uniquement pour Porte Lourde",IF(AE16>0,"⚠ Option T/M incompatible avec la gamme",IF(V16=0,IF(AC16>0,AC16,""),IF(V16=-1,"⚠ Dimension non disponible",(V16+W16+X16+Z16+AA16+AB16+AD16)*(1-Paramètres!$B$2)+AC16)))),""))+IF($L16="OUI",25,0),IF(IFERROR(OR(AND($G16<>"",IFERROR(VLOOKUP($C16,_Données!$A$196:$E$211,2,FALSE()),"")<>"",OR($G16<VLOOKUP($C16,_Données!$A$196:$E$211,2,FALSE()),$G16>VLOOKUP($C16,_Données!$A$196:$E$211,3,FALSE()))),AND($H16<>"",IFERROR(VLOOKUP($C16,_Données!$A$196:$E$211,4,FALSE()),"")<>"",OR($H16<VLOOKUP($C16,_Données!$A$196:$E$211,4,FALSE()),$H16>VLOOKUP($C16,_Données!$A$196:$E$211,5,FALSE())))),FALSE),"",IFERROR(IF(AND($R16<>"",$R16<>"Aucune option",NOT(OR($C16="Porte Lourde 1 vantail",$C16="Porte Lourde 2 vantaux"))),"⚠ Option valable uniquement pour Porte Lourde",IF(AE16>0,"⚠ Option T/M incompatible avec la gamme",IF(V16=0,IF(AC16>0,AC16,""),IF(V16=-1,"⚠ Dimension non disponible",(V16+W16+X16+Z16+AA16+AB16+AD16)*(1-Paramètres!$B$2)+AC16)))),""))),"")),"") | T16: =IFERROR(IF(OR(S16="",ISTEXT(S16)),"",S16*$I16),"") | V16: =IFERROR(IF(OR($C16="",$G16="",$H16=""),0,IF(INDIRECT("'"&VLOOKUP($C16,_Données!$A$3:$V$18,2,FALSE())&"'!"&ADDRESS((VLOOKUP($C16,_Données!$A$3:$V$18,12,FALSE())+IFERROR(MATCH(MAX(VLOOKUP($C16,_Données!$A$3:$V$18,18,FALSE()),MIN(VLOOKUP($C16,_Données!$A$3:$V$18,6,FALSE()),(VLOOKUP($C16,_Données!$A$3:$V$18,18,FALSE())+ROUND(($H16-VLOOKUP($C16,_Données!$A$3:$V$18,18,FALSE()))/VLOOKUP($C16,_Données!$A$3:$V$18,19,FALSE()),0)*VLOOKUP($C16,_Données!$A$3:$V$18,19,FALSE())))),INDIRECT("'"&VLOOKUP($C16,_Données!$A$3:$V$18,2,FALSE())&"'!"&ADDRESS(VLOOKUP($C16,_Données!$A$3:$V$18,12,FALSE()),1,4)&":"&ADDRESS(VLOOKUP($C16,_Données!$A$3:$V$18,12,FALSE())+VLOOKUP($C16,_Données!$A$3:$V$18,15,FALSE())-1,1,4)),0),MATCH(MAX(VLOOKUP($C16,_Données!$A$3:$V$18,18,FALSE()),MIN(VLOOKUP($C16,_Données!$A$3:$V$18,6,FALSE()),(VLOOKUP($C16,_Données!$A$3:$V$18,18,FALSE())+ROUND(($H16-VLOOKUP($C16,_Données!$A$3:$V$18,18,FALSE()))/VLOOKUP($C16,_Données!$A$3:$V$18,19,FALSE()),0)*VLOOKUP($C16,_Données!$A$3:$V$18,19,FALSE())))),INDIRECT("'"&VLOOKUP($C16,_Données!$A$3:$V$18,2,FALSE())&"'!"&ADDRESS(VLOOKUP($C16,_Données!$A$3:$V$18,12,FALSE()),1,4)&":"&ADDRESS(VLOOKUP($C16,_Données!$A$3:$V$18,12,FALSE())+VLOOKUP($C16,_Données!$A$3:$V$18,15,FALSE())-1,1,4)),1))-1),(VLOOKUP($C16,_Données!$A$3:$V$18,13,FALSE())+IFERROR(MATCH(MAX(VLOOKUP($C16,_Données!$A$3:$V$18,16,FALSE()),MIN(VLOOKUP($C16,_Données!$A$3:$V$18,4,FALSE()),(VLOOKUP($C16,_Données!$A$3:$V$18,16,FALSE())+ROUND(($G16-VLOOKUP($C16,_Données!$A$3:$V$18,16,FALSE()))/VLOOKUP($C16,_Données!$A$3:$V$18,17,FALSE()),0)*VLOOKUP($C16,_Données!$A$3:$V$18,17,FALSE())))),INDIRECT("'"&VLOOKUP($C16,_Données!$A$3:$V$18,2,FALSE())&"'!"&ADDRESS(VLOOKUP($C16,_Données!$A$3:$V$18,12,FALSE())-1,VLOOKUP($C16,_Données!$A$3:$V$18,13,FALSE()),4)&":"&ADDRESS(VLOOKUP($C16,_Données!$A$3:$V$18,12,FALSE())-1,VLOOKUP($C16,_Données!$A$3:$V$18,13,FALSE())+VLOOKUP($C16,_Données!$A$3:$V$18,14,FALSE())-1,4)),0),MATCH(MAX(VLOOKUP($C16,_Données!$A$3:$V$18,16,FALSE()),MIN(VLOOKUP($C16,_Données!$A$3:$V$18,4,FALSE()),(VLOOKUP($C16,_Données!$A$3:$V$18,16,FALSE())+ROUND(($G16-VLOOKUP($C16,_Données!$A$3:$V$18,16,FALSE()))/VLOOKUP($C16,_Données!$A$3:$V$18,17,FALSE()),0)*VLOOKUP($C16,_Données!$A$3:$V$18,17,FALSE())))),INDIRECT("'"&VLOOKUP($C16,_Données!$A$3:$V$18,2,FALSE())&"'!"&ADDRESS(VLOOKUP($C16,_Données!$A$3:$V$18,12,FALSE())-1,VLOOKUP($C16,_Données!$A$3:$V$18,13,FALSE()),4)&":"&ADDRESS(VLOOKUP($C16,_Données!$A$3:$V$18,12,FALSE())-1,VLOOKUP($C16,_Données!$A$3:$V$18,13,FALSE())+VLOOKUP($C16,_Données!$A$3:$V$18,14,FALSE())-1,4)),1))-1),4))="",-1,INDIRECT("'"&VLOOKUP($C16,_Données!$A$3:$V$18,2,FALSE())&"'!"&ADDRESS((VLOOKUP($C16,_Données!$A$3:$V$18,12,FALSE())+IFERROR(MATCH(MAX(VLOOKUP($C16,_Données!$A$3:$V$18,18,FALSE()),MIN(VLOOKUP($C16,_Données!$A$3:$V$18,6,FALSE()),(VLOOKUP($C16,_Données!$A$3:$V$18,18,FALSE())+ROUND(($H16-VLOOKUP($C16,_Données!$A$3:$V$18,18,FALSE()))/VLOOKUP($C16,_Données!$A$3:$V$18,19,FALSE()),0)*VLOOKUP($C16,_Données!$A$3:$V$18,19,FALSE())))),INDIRECT("'"&VLOOKUP($C16,_Données!$A$3:$V$18,2,FALSE())&"'!"&ADDRESS(VLOOKUP($C16,_Données!$A$3:$V$18,12,FALSE()),1,4)&":"&ADDRESS(VLOOKUP($C16,_Données!$A$3:$V$18,12,FALSE())+VLOOKUP($C16,_Données!$A$3:$V$18,15,FALSE())-1,1,4)),0),MATCH(MAX(VLOOKUP($C16,_Données!$A$3:$V$18,18,FALSE()),MIN(VLOOKUP($C16,_Données!$A$3:$V$18,6,FALSE()),(VLOOKUP($C16,_Données!$A$3:$V$18,18,FALSE())+ROUND(($H16-VLOOKUP($C16,_Données!$A$3:$V$18,18,FALSE()))/VLOOKUP($C16,_Données!$A$3:$V$18,19,FALSE()),0)*VLOOKUP($C16,_Données!$A$3:$V$18,19,FALSE())))),INDIRECT("'"&VLOOKUP($C16,_Données!$A$3:$V$18,2,FALSE())&"'!"&ADDRESS(VLOOKUP($C16,_Données!$A$3:$V$18,12,FALSE()),1,4)&":"&ADDRESS(VLOOKUP($C16,_Données!$A$3:$V$18,12,FALSE())+VLOOKUP($C16,_Données!$A$3:$V$18,15,FALSE())-1,1,4)),1))-1),(VLOOKUP($C16,_Données!$A$3:$V$18,13,FALSE())+IFERROR(MATCH(MAX(VLOOKUP($C16,_Données!$A$3:$V$18,16,FALSE()),MIN(VLOOKUP($C16,_Données!$A$3:$V$18,4,FALSE()),(VLOOKUP($C16,_Données!$A$3:$V$18,16,FALSE())+ROUND(($G16-VLOOKUP($C16,_Données!$A$3:$V$18,16,FALSE()))/VLOOKUP($C16,_Données!$A$3:$V$18,17,FALSE()),0)*VLOOKUP($C16,_Données!$A$3:$V$18,17,FALSE())))),INDIRECT("'"&VLOOKUP($C16,_Données!$A$3:$V$18,2,FALSE())&"'!"&ADDRESS(VLOOKUP($C16,_Données!$A$3:$V$18,12,FALSE())-1,VLOOKUP($C16,_Données!$A$3:$V$18,13,FALSE()),4)&":"&ADDRESS(VLOOKUP($C16,_Données!$A$3:$V$18,12,FALSE())-1,VLOOKUP($C16,_Données!$A$3:$V$18,13,FALSE())+VLOOKUP($C16,_Données!$A$3:$V$18,14,FALSE())-1,4)),0),MATCH(MAX(VLOOKUP($C16,_Données!$A$3:$V$18,16,FALSE()),MIN(VLOOKUP($C16,_Données!$A$3:$V$18,4,FALSE()),(VLOOKUP($C16,_Données!$A$3:$V$18,16,FALSE())+ROUND(($G16-VLOOKUP($C16,_Données!$A$3:$V$18,16,FALSE()))/VLOOKUP($C16,_Données!$A$3:$V$18,17,FALSE()),0)*VLOOKUP($C16,_Données!$A$3:$V$18,17,FALSE())))),INDIRECT("'"&VLOOKUP($C16,_Données!$A$3:$V$18,2,FALSE())&"'!"&ADDRESS(VLOOKUP($C16,_Données!$A$3:$V$18,12,FALSE())-1,VLOOKUP($C16,_Données!$A$3:$V$18,13,FALSE()),4)&":"&ADDRESS(VLOOKUP($C16,_Données!$A$3:$V$18,12,FALSE())-1,VLOOKUP($C16,_Données!$A$3:$V$18,13,FALSE())+VLOOKUP($C16,_Données!$A$3:$V$18,14,FALSE())-1,4)),1))-1),4)))),0) -> 0 | W16: =IFERROR(IF(V16=0,0,IF(MAX(VLOOKUP($C16,_Données!$A$3:$V$18,18,FALSE()),MIN(VLOOKUP($C16,_Données!$A$3:$V$18,6,FALSE()),(VLOOKUP($C16,_Données!$A$3:$V$18,18,FALSE())+ROUND(($H16-VLOOKUP($C16,_Données!$A$3:$V$18,18,FALSE()))/VLOOKUP($C16,_Données!$A$3:$V$18,19,FALSE()),0)*VLOOKUP($C16,_Données!$A$3:$V$18,19,FALSE()))))>=VLOOKUP($C16,_Données!$A$3:$V$18,10,FALSE()),V16*VLOOKUP($C16,_Données!$A$3:$V$18,11,FALSE()),0)),0) -> 0 | X16: =IFERROR(IF(OR($D16="",V16=0),0,V16*VLOOKUP($D16,_Données!$A$21:$C$28,2,FALSE())),0) -> 0 | Y16: =IFERROR(IF($D16="",0,VLOOKUP($D16,_Données!$A$21:$C$28,3,FALSE())),0) -> 0 | Z16: =IFERROR(IF($E16="",0,VLOOKUP($E16,_Données!$A$48:$C$104,2,FALSE())),0) -> 0 | AA16: =IFERROR(IF(OR($F16="",$G16="",$H16=""),0,VLOOKUP($F16,_Données!$A$33:$C$43,2,FALSE())*2*($G16+$H16)/1000),0) -> 0 | AB16: =IFERROR(IF(OR($F16="",V16=0),0,V16*VLOOKUP($F16,_Données!$A$33:$C$43,3,FALSE())),0) -> 0 | AC16: =IFERROR(IF(OR($R16="",$R16="Aucune option",NOT(OR($C16="Porte Lourde 1 vantail",$C16="Porte Lourde 2 vantaux"))),0,VLOOKUP($R16,_Données!$A$109:$C$125,2,FALSE())*0.75*IF(VLOOKUP($R16,_Données!$A$109:$C$125,3,FALSE())=1,IF($C16="Porte Lourde 1 vantail",1,IF($C16="Porte Lourde 2 vantaux",2,1)),1)*(1-Paramètres!$B$2)),0) -> 0 | AD16: =IFERROR(IF(OR($M16="",$M16="Aucune"),0,VLOOKUP($C16&"|"&$M16,_Données!$A$132:$B$146,2,FALSE())*IF(LEFT($M16,8)="Traverse",$G16,$H16)/1000),0)+IFERROR(IF(OR($N16="",$N16="Aucune"),0,VLOOKUP($C16&"|"&$N16,_Données!$A$132:$B$146,2,FALSE())*IF(LEFT($N16,8)="Traverse",$G16,$H16)/1000),0)+IFERROR(IF(OR($O16="",$O16="Aucune"),0,VLOOKUP($C16&"|"&$O16,_Données!$A$132:$B$146,2,FALSE())*IF(LEFT($O16,8)="Traverse",$G16,$H16)/1000),0) -> 0 | AE16: =IF(AND($M16<>"",$M16<>"Aucune"),IF(ISNA(VLOOKUP($C16&"|"&$M16,_Données!$A$132:$B$146,2,FALSE())),1,0),0)+IF(AND($N16<>"",$N16<>"Aucune"),IF(ISNA(VLOOKUP($C16&"|"&$N16,_Données!$A$132:$B$146,2,FALSE())),1,0),0)+IF(AND($O16<>"",$O16<>"Aucune"),IF(ISNA(VLOOKUP($C16&"|"&$O16,_Données!$A$132:$B$146,2,FALSE())),1,0),0) -> 0 | AF16: =IF(LEFT($M16,8)="Traverse",$M16,"") | AG16: =IF(LEFT($N16,8)="Traverse",$N16,"") | AH16: =IF(LEFT($O16,8)="Traverse",$O16,"") | AI16: =IF(LEFT($M16,6)="Meneau",$M16,"") | AJ16: =IF(LEFT($N16,6)="Meneau",$N16,"") | AK16: =IF(LEFT($O16,6)="Meneau",$O16,"") | AL16: =IF(AND(AF16="",AG16="",AH16=""),"",CHAR(10)&"Traverses : "&AF16&IF(AND(AF16<>"",AG16<>""),", ","")&AG16&IF(AND(OR(AF16<>"",AG16<>""),AH16<>""),", ","")&AH16) | AM16: =IF(AND(AI16="",AJ16="",AK16=""),"",CHAR(10)&"Meneaux : "&AI16&IF(AND(AI16<>"",AJ16<>""),", ","")&AJ16&IF(AND(OR(AI16<>"",AJ16<>""),AK16<>""),", ","")&AK16)
